Workbook

Sheet Sheet1
B1: Date | C1: Study | D1: Exercise | E1: Reading | F1: Coding | G1: Total Done | H1: Progress %
B2: 46082 | C2: 0 | D2: 1 | E2: 1 | F2: 0 | G2: =SUM(Sheet1!$C2:$F2) -> 2 | H2: =Sheet1!$G2/4 -> 0.5
B3: 46083 | C3: 1 | D3: 0 | E3: 1 | F3: 1 | G3: =SUM(Sheet1!$C3:$F3) -> 3 | H3: =Sheet1!$G3/4 -> 0.75
B4: 46084 | C4: 1 | D4: 1 | E4: 1 | F4: 1 | G4: =SUM(Sheet1!$C4:$F4) -> 4 | H4: =Sheet1!$G4/4 -> 1
B5: 46085 | C5: 0 | D5: 1 | E5: 1 | F5: 0 | G5: =SUM(Sheet1!$C5:$F5) -> 2 | H5: =Sheet1!$G5/4 -> 0.5
B6: 46086 | C6: 1 | D6: 1 | E6: 1 | F6: 1 | G6: =SUM(Sheet1!$C6:$F6) -> 4 | H6: =Sheet1!$G6/4 -> 1
B7: 46087 | C7: 0 | D7: 0 | E7: 1 | F7: 0 | G7: =SUM(Sheet1!$C7:$F7) -> 1 | H7: =Sheet1!$G7/4 -> 0.25
B8: 46088 | C8: 1 | D8: 0 | E8: 1 | F8: 1 | G8: =SUM(Sheet1!$C8:$F8) -> 3 | H8: =Sheet1!$G8/4 -> 0.75
B9: 46089 | C9: 1 | D9: 1 | E9: 0 | F9: 1 | G9: =SUM(Sheet1!$C9:$F9) -> 3 | H9: =Sheet1!$G9/4 -> 0.75
B10: 46090 | C10: 1 | D10: 0 | E10: 1 | F10: 1 | G10: =SUM(Sheet1!$C10:$F10) -> 3 | H10: =Sheet1!$G10/4 -> 0.75
B11: 46091 | C11: 1 | D11: 1 | E11: 1 | F11: 1 | G11: =SUM(Sheet1!$C11:$F11) -> 4 | H11: =Sheet1!$G11/4 -> 1
B12: 46092 | C12: 1 | D12: 0 | E12: 1 | F12: 1 | G12: =SUM(Sheet1!$C12:$F12) -> 3 | H12: =Sheet1!$G12/4 -> 0.75
B13: 46093 | C13: 0 | D13: 1 | E13: 1 | F13: 0 | G13: =SUM(Sheet1!$C13:$F13) -> 2 | H13: =Sheet1!$G13/4 -> 0.5
... B22: 46102 | C22: 1 | D22: 1 | E22: 1 | F22: 1 | G22: =SUM(Sheet1!$C22:$F22) -> 4 | H22: =Sheet1!$G22/4 -> 1
B23: 46103 | C23: 1 | D23: 1 | E23: 1 | F23: 1 | G23: =SUM(Sheet1!$C23:$F23) -> 4 | H23: =Sheet1!$G23/4 -> 1 | K23: Metric | L23: Value
B24: 46104 | C24: 0 | D24: 1 | E24: 1 | F24: 1 | G24: =SUM(Sheet1!$C24:$F24) -> 3 | H24: =Sheet1!$G24/4 -> 0.75 | K24: Total Days | L24: =COUNTA(Table5[Date]) -> 31
B25: 46105 | C25: 1 | D25: 0 | E25: 1 | F25: 1 | G25: =SUM(Sheet1!$C25:$F25) -> 3 | H25: =Sheet1!$G25/4 -> 0.75 | K25: Total Habits Done | L25: =SUM(Table5[Total Done]) -> 83
B26: 46106 | C26: 0 | D26: 0 | E26: 1 | F26: 1 | G26: =SUM(Sheet1!$C26:$F26) -> 2 | H26: =Sheet1!$G26/4 -> 0.5 | K26: Completion% | L26: =SUM(Table5[Total Done])/(4*COUNTA(Table5[Date])) -> 0.66935484
B27: 46107 | C27: 1 | D27: 1 | E27: 0 | F27: 0 | G27: =SUM(Sheet1!$C27:$F27) -> 2 | H27: =Sheet1!$G27/4 -> 0.5 | K27: Remaining | L27: =1-L26 -> 0.33064516
B28: 46108 | C28: 1 | D28: 0 | E28: 1 | F28: 1 | G28: =SUM(Sheet1!$C28:$F28) -> 3 | H28: =Sheet1!$G28/4 -> 0.75
B29: 46109 | C29: 1 | D29: 1 | E29: 0 | F29: 1 | G29: =SUM(Sheet1!$C29:$F29) -> 3 | H29: =Sheet1!$G29/4 -> 0.75
B30: 46110 | C30: 0 | D30: 0 | E30: 1 | F30: 0 | G30: =SUM(Sheet1!$C30:$F30) -> 1 | H30: =Sheet1!$G30/4 -> 0.25
B31: 46111 | C31: 1 | D31: 0 | E31: 0 | F31: 1 | G31: =SUM(Sheet1!$C31:$F31) -> 2 | H31: =Sheet1!$G31/4 -> 0.5
B32: 46112 | C32: 0 | D32: 1 | E32: 1 | F32: 0 | G32: =SUM(Sheet1!$C32:$F32) -> 2 | H32: =Sheet1!$G32/4 -> 0.5

Sheet Sheet2
A1: Column1 | B1: Column2 | C1: Column3 | D1: Column4 | E1: Column5 | F1: Column6 | G1: Column7
A12: Date | B12: Study | C12: Exercise | D12: Reading | E12: Coding | F12: Total Done | G12: Progress %
A13: 46082 | B13: 0 | C13: 1 | D13: 1 | E13: 0 | F13: =SUM(Sheet1!$C13:$F13) -> 2 | G13: =Sheet1!$G13/4 -> 0.5
A14: 46083 | B14: 1 | C14: 0 | D14: 1 | E14: 1 | F14: =SUM(Sheet1!$C14:$F14) -> 4 | G14: =Sheet1!$G14/4 -> 1
A15: 46084 | B15: 1 | C15: 1 | D15: 1 | E15: 1 | F15: =SUM(Sheet1!$C15:$F15) -> 2 | G15: =Sheet1!$G15/4 -> 0.5
A16: 46085 | B16: 0 | C16: 1 | D16: 1 | E16: 0 | F16: =SUM(Sheet1!$C16:$F16) -> 1 | G16: =Sheet1!$G16/4 -> 0.25
A17: 46086 | B17: 1 | C17: 1 | D17: 1 | E17: 1 | F17: =SUM(Sheet1!$C17:$F17) -> 1 | G17: =Sheet1!$G17/4 -> 0.25
A18: 46087 | B18: 0 | C18: 0 | D18: 1 | E18: 0 | F18: =SUM(Sheet1!$C18:$F18) -> 3 | G18: =Sheet1!$G18/4 -> 0.75
A19: 46088 | B19: 1 | C19: 0 | D19: 1 | E19: 1 | F19: =SUM(Sheet1!$C19:$F19) -> 1 | G19: =Sheet1!$G19/4 -> 0.25
A20: 46089 | B20: 1 | C20: 1 | D20: 0 | E20: 1 | F20: =SUM(Sheet1!$C20:$F20) -> 4 | G20: =Sheet1!$G20/4 -> 1
A21: 46090 | B21: 1 | C21: 0 | D21: 1 | E21: 1 | F21: =SUM(Sheet1!$C21:$F21) -> 4 | G21: =Sheet1!$G21/4 -> 1
A22: 46091 | B22: 1 | C22: 1 | D22: 1 | E22: 1 | F22: =SUM(Sheet1!$C22:$F22) -> 4 | G22: =Sheet1!$G22/4 -> 1
A23: 46092 | B23: 1 | C23: 0 | D23: 1 | E23: 1 | F23: =SUM(Sheet1!$C23:$F23) -> 4 | G23: =Sheet1!$G23/4 -> 1
A24: 46093 | B24: 0 | C24: 1 | D24: 1 | E24: 0 | F24: =SUM(Sheet1!$C24:$F24) -> 3 | G24: =Sheet1!$G24/4 -> 0.75
... A30: 46099 | B30: 0 | C30: 0 | D30: 1 | E30: 0 | F30: =SUM(Sheet1!$C30:$F30) -> 1 | G30: =Sheet1!$G30/4 -> 0.25
A31: 46100 | B31: 1 | C31: 1 | D31: 1 | E31: 1 | F31: =SUM(Sheet1!$C31:$F31) -> 2 | G31: =Sheet1!$G31/4 -> 0.5 | L31: Date | M31: Study | N31: Exercise | O31: Reading | P31: Coding | Q31: Total Done | R31: Progress %
A32: 46101 | B32: 1 | C32: 1 | D32: 1 | E32: 1 | F32: =SUM(Sheet1!$C32:$F32) -> 2 | G32: =Sheet1!$G32/4 -> 0.5 | L32: 46082 | M32: 0 | N32: 1 | O32: 1 | P32: 0 | Q32: 2 | R32: 0.5
A33: 46102 | B33: 1 | C33: 1 | D33: 1 | E33: 1 | F33: =SUM(Sheet1!$C33:$F33) -> 0 | G33: =Sheet1!$G33/4 -> 0 | L33: 46083 | M33: 1 | N33: 0 | O33: 1 | P33: 1 | Q33: 3 | R33: 0.75
A34: 46103 | B34: 1 | C34: 1 | D34: 1 | E34: 1 | F34: =SUM(Sheet1!$C34:$F34) -> 0 | G34: =Sheet1!$G34/4 -> 0 | L34: 46084 | M34: 1 | N34: 1 | O34: 1 | P34: 1 | Q34: 4 | R34: 1
A35: 46104 | B35: 0 | C35: 1 | D35: 1 | E35: 1 | F35: =SUM(Sheet1!$C35:$F35) -> 0 | G35: =Sheet1!$G35/4 -> 0 | L35: 46085 | M35: 0 | N35: 1 | O35: 1 | P35: 0 | Q35: 2 | R35: 0.5
A36: 46105 | B36: 1 | C36: 0 | D36: 1 | E36: 1 | F36: =SUM(Sheet1!$C36:$F36) -> 0 | G36: =Sheet1!$G36/4 -> 0 | L36: 46086 | M36: 1 | N36: 1 | O36: 1 | P36: 1 | Q36: 4 | R36: 1
A37: 46106 | B37: 0 | C37: 0 | D37: 1 | E37: 1 | F37: =SUM(Sheet1!$C37:$F37) -> 0 | G37: =Sheet1!$G37/4 -> 0 | L37: 46087 | M37: 0 | N37: 0 | O37: 1 | P37: 0 | Q37: 1 | R37: 0.25
A38: 46107 | B38: 1 | C38: 1 | D38: 0 | E38: 0 | F38: =SUM(Sheet1!$C38:$F38) -> 0 | G38: =Sheet1!$G38/4 -> 0 | L38: 46088 | M38: 1 | N38: 0 | O38: 1 | P38: 1 | Q38: 3 | R38: 0.75
A39: 46108 | B39: 1 | C39: 0 | D39: 1 | E39: 1 | F39: =SUM(Sheet1!$C39:$F39) -> 0 | G39: =Sheet1!$G39/4 -> 0 | L39: 46089 | M39: 1 | N39: 1 | O39: 0 | P39: 1 | Q39: 3 | R39: 0.75
A40: 46109 | B40: 1 | C40: 1 | D40: 0 | E40: 1 | F40: =SUM(Sheet1!$C40:$F40) -> 0 | G40: =Sheet1!$G40/4 -> 0 | L40: 46090 | M40: 1 | N40: 0 | O40: 1 | P40: 1 | Q40: 3 | R40: 0.75
A41: 46110 | B41: 0 | C41: 0 | D41: 1 | E41: 0 | F41: =SUM(Sheet1!$C41:$F41) -> 0 | G41: =Sheet1!$G41/4 -> 0 | L41: 46091 | M41: 1 | N41: 1 | O41: 1 | P41: 1 | Q41: 4 | R41: 1
A42: 46111 | B42: 1 | C42: 0 | D42: 0 | E42: 1 | F42: =SUM(Sheet1!$C42:$F42) -> 0 | G42: =Sheet1!$G42/4 -> 0 | L42: 46092 | M42: 1 | N42: 0 | O42: 1 | P42: 1 | Q42: 3 | R42: 0.75
A43: 46112 | B43: 0 | C43: 1 | D43: 1 | E43: 0 | F43: =SUM(Sheet1!$C43:$F43) -> 0 | G43: =Sheet1!$G43/4 -> 0 | L43: 46093 | M43: 0 | N43: 1 | O43: 1 | P43: 0 | Q43: 2 | R43: 0.5
L44: 46094 | M44: 1 | N44: 1 | O44: 1 | P44: 1 | Q44: 4 | R44: 1
L45: 46095 | M45: 0 | N45: 1 | O45: 1 | P45: 0 | Q45: 2 | R45: 0.5
L46: 46096 | M46: 0 | N46: 0 | O46: 1 | P46: 0 | Q46: 1 | R46: 0.25
L47: 46097 | M47: 0 | N47: 0 | O47: 1 | P47: 0 | Q47: 1 | R47: 0.25
L48: 46098 | M48: 1 | N48: 1 | O48: 0 | P48: 1 | Q48: 3 | R48: 0.75
L49: 46099 | M49: 0 | N49: 0 | O49: 1 | P49: 0 | Q49: 1 | R49: 0.25
L50: 46100 | M50: 1 | N50: 1 | O50: 1 | P50: 1 | Q50: 4 | R50: 1
L51: 46101 | M51: 1 | N51: 1 | O51: 1 | P51: 1 | Q51: 4 | R51: 1
L52: 46102 | M52: 1 | N52: 1 | O52: 1 | P52: 1 | Q52: 4 | R52: 1
L53: 46103 | M53: 1 | N53: 1 | O53: 1 | P53: 1 | Q53: 4 | R53: 1
L54: 46104 | M54: 0 | N54: 1 | O54: 1 | P54: 1 | Q54: 3 | R54: 0.75
L55: 46105 | M55: 1 | N55: 0 | O55: 1 | P55: 1 | Q55: 3 | R55: 0.75
...
